Workbook
Name c_fix: Parameters_Ex2A!$E$17
Name c_post_coun_n: Parameters_Ex2A!$E$22
Name c_post_coun_p: Parameters_Ex2A!$E$20
Name c_precoun: Parameters_Ex2A!$E$18
Name c_treat: Parameters_Ex2A!$E$21
Name c_var_screen: Parameters_Ex2A!$E$19
Name costInt: [1]HIV_Parameters!$C$11
Name costTest: [1]HIV_Parameters!$C$10
Name d_inf_untx: Parameters_Ex2A!$E$10
Name d_tx_e: Parameters_Ex2A!$E$11
Name d_tx_l: Parameters_Ex2A!$E$12
Name d_uninf: Parameters_Ex2A!$E$9
Name life_exp: Parameters_Ex2A!$E$16
Name n_pop: Parameters_Ex2A!$E$3
Name p_attend: Parameters_Ex2A!$E$4
Name p_early: Parameters_Ex2A!$E$8
Name p_prev: Parameters_Ex2A!$E$5
Name p_screen_inf: Parameters_Ex2A!$E$6
Name p_screen_uninf: Parameters_Ex2A!$E$7
Name p_treat_all: Parameters_Ex2A!$E$15
Name pHIV: [1]HIV_Parameters!$C$6
Name pHIVTknInt: [1]HIV_Parameters!$C$8
Name pHIVTunkn: [1]HIV_Parameters!$C$7
Name pInt: [1]HIV_Parameters!$C$9
Name sens: Parameters_Ex2A!$E$13
Name spec: Parameters_Ex2A!$E$14

Sheet Narrative
A1: Background
A2: Imagine that you have been asked to advise national decision-makers on the cost-effectiveness of improving syphilis management in antenatal care in rural Tanzania. Syphilis in pregnancy is a major contributor to adverse outcomes, including stillbirths, neonatal deaths, and early infant morbidity. National policy recommends routine screening of all pregnant women. However, implementation is incomplete—approximately 50% of rural facilities do not currently offer screening or treatment services. As a result, decision-makers are considering alternative strategies to improve pregnancy outcomes in clinics where no testing is currently available. To inform this decision, you will undertake a decision-analytic economic evaluation comparing three policy options: • No intervention (status quo) • Screen and treat • Treat all without screening You conduct a review of the available literature and programme data, and compile the following inputs for your model.
A3: The data
A4: From published studies, programme reports, and routine data sources, you identify the following information:
A5: Population and epidemiology • The annual number of women attending antenatal clinics is estimated at 1,000 (routine clinic data). • The probability that a pregnant woman attends antenatal care is 0.88 (TZ DHS 2016; Kuznik 2013; Magoma 2010; Terris-Prestholt 2015). • The prevalence of syphilis infection among pregnant women is 10.9% (Mabey 2012; Sweeney 2014; Gomez 2013; Nnko 2015; local data).
A6: Screening and care-seeking behaviour • Among infected women attending care, the probability of being screened is 0.90 (TZ DHS 2016; Mabey 2012; TSPA 2015). • Among uninfected women, the probability of being screened is also assumed to be 0.90 (TZ DHS 2016; Mabey 2012). • The probability that women present early in pregnancy (1st or 2nd trimester) is 0.667 (Cha 2016; DHS 2015–2016; TZ 2015).
A7: Test performance • The sensitivity of the rapid plasma reagin (RPR) test is 0.85 (Rogozinska 2016; Casas 2018; Tucker 2010). • The specificity of the test is 0.97 (Rogozinska 2016; Casas 2018; Tucker 2011).
A8: Health outcomes • Among uninfected women, the probability of perinatal death is 0.076 (Cha 2017; Kuznik 2013). • Among infected women who are not treated, the probability of perinatal death is 0.379 (Cha 2017; Kuznik 2013; Gomez 2013). • Among infected women who are treated, the probability of perinatal death is 0.216, regardless of timing of treatment (Kuznik 2013; Temmerman 2000; Watson-Jones 2002).
A9: Costs From programme data and published estimates, you identify the following costs (per woman): • Fixed programme cost: 0.84 • Pre-counselling: 0.05 • Screening test: 1.64 • Post-counselling (positive): 1.13 • Post-counselling (negative): 0.19 • Treatment: 1.93 Where cost data were not directly available in the literature, estimates were derived from programme budgets and expert input.
A10: Assumptions • In the “treat all” strategy, all women attending care receive treatment. • All women who test positive are assumed to receive treatment. • Outcomes are measured over a one-year analytic horizon, consistent with programme implementation and expected timing of outcomes. • Life expectancy at birth is assumed to be 55 years for the purpose of calculating years of life lost.

Sheet Parameters_Ex2A
A1: PARAMETER TABLE
A2: Description | B2: Names | C2: Names by convention | D2: Names by convention (easier to understand) | E2: Base-value | F2: Lower-bound | G2: Upperbound | H2: Source
A3: Population attending antenatal clinics in one year | B3: Pop | H3: Annual clinic data
A4: ANC attendance probability | B4: Attend | D4: p_attend | F4: 0.88 | G4: 1 | H4: TZ DHS 2016; Kuznik 2013; local data; Kearns 2014; Magoma 2010; Terris-Prestholt 2015
A5: Overall prevalence of infection in pregnant women | B5: Prev | E5: 0.109 | F5: 0.051 | G5: 0.18 | H5: Mabey 2012; Sweeney 2014; Gomez 2013; Nnko 2015; local data
A6: Probability of screening uptake if infected | B6: ScreenGP | F6: 0.17 | G6: 1 | H6: TZ DHS 2016; Mabey 2012; local data; TSPA 2015
A7: Probability of screening uptake if uninfected | B7: ScreenGN | E7: 0.9 | H7: TZ DHS 2016; Mabey 2012; local data
A8: Probability of presenting early to ANC (1st/2nd trimester) | B8: PresentE | F8: 0.15 | G8: 0.667 | H8: Cha 2016; DHS 2015–2016; TZ 2015
A9: Perinatal mortality in uninfected women | B9: DeathU | E9: 0.076 | H9: Cha 2017; Kuznik 2013
A10: Perinatal mortality in infected untreated women | B10: DeathIWOT | C10: d_iwot | D10: d_inf_untx | E10: 0.379 | F10: 0.238 | G10: 0.575 | H10: Cha 2017; Kuznik 2013; Genc 2000; CDC 2017; De Santis 2012; Gomez 2013
A11: Perinatal mortality in infected treated women presenting early | B11: DeathITE | C11: d_ite | D11: d_tx_e | E11: 0.216 | H11: Kuznik 2013; Temmerman 2000; Watson-Jones 2002; Kanyangarar 2018
A12: Perinatal mortality in infected treated women presenting late | B12: DeathITL | E12: 0.216 | H12: Kuznik 2013; Temmerman 2000; Watson-Jones 2002
A13: Qualitative RPR sensitivity | B13: Sen | E13: 0.85 | F13: 0.29 | G13: 0.98 | H13: Rogozinska 2016; Casas 2018; Tucker 2010
A14: Qualitative RPR specificity | B14: Spec | F14: 0.89 | G14: 1 | H14: Rogozinska 2016; Casas 2018; Tucker 2011
A15: Probability of treatment in Treat All strategy | B15: TreatAll | E15: 1 | F15: 1 | G15: 1 | H15: Terris-Prestholt 2015
A16: Life expectancy for YLL calculation | B16: LifeExp | E16: 55
A17: Fixed programme cost per woman | B17: cFix | H17: Programme data
A18: Pre-counselling cost per woman | B18: cPreCoun | H18: Programme data
A19: Variable screening cost per woman screened | B19: cVarScreen | E19: 1.64 | H19: Programme data
A20: Post-counselling cost per positive result | B20: cPostCounP | H20: Programme data
A21: Treatment cost per woman treated | B21: cTreat | F21: 0.11 | G21: 0.948 | H21: Sweeney 2014; Nnko 2016
A22: Post-counselling cost per negative result | B22: cPostCounN | H22: Programme data
A24: Exercise 2A: Parameter Table & Naming Convention
A25: Objective
A26: To understand the parameter table structure, apply a consistent naming convention, and create named parameters in Excel.
A27: Step 1: Understand the Parameter Table
A28: Each column serves a specific purpose:
A29: • Description: Plain-language explanation of the parameter
A30: • Names: Original name (from slides/Amua)
A31: • Names by convention: Technical naming using standard rules (see table below)
A32: • Names by convention (easier to understand): Clean, readable names for use in formulas i.e. is there a way you could name this to best suit your understandng of the parameter, so it is easier to recall. This may be different for everyone- lets give it a go.
A33: • Base-value: Value used in the model
A34: • Lower-bound / Upperbound: Used later for sensitivity analysis
A35: • Source: Data source or reference
... A37: Complete any missing entries in the “Names by convention (easier to understand)” column using these rules:
A38: Prefix | B38: Meaning | C38: Example
A39: p_ | B39: Probability (tree parameters) | C39: p_prev, p_attend
A40: c_ | B40: Cost parameters | C40: c_treat, c_screen
A41: d_ | B41: Death outcomes | C41: d_uninf, d_inf_untx
A42: n_ | B42: Numbers / population counts | C42: n_pop
...

Sheet DT_instructions_Ex2B
A1: Exercise 2B: Building and Parameterising the Decision Tree (<DT_template> Sheet)
A2: Objective
A3: To construct the decision tree for the syphilis case study, assign probabilities and outcomes to each pathway, and prepare for calculating expected values.
A4: Step 1: Navigate to the DT sheet
A5: Go to the DT tab.
A6: You will see a set of shapes in A1:D12:
A7: • Square = decision node
A8: • Circle = chance node
A9: • Triangle = terminal node
A10: The connector lines are anchored to the shapes, so if you move a shape, the line will move with it.
A11: Step 2: Review the structure provided
A12: From the decision node, three policy options are already drawn:
... A85: If the pathways are incorrect, the results will be incorrect.

Sheet DT_template_Ex2B_C
F1: Syphilis Decision Tree | S1: Pathway Probs | U1: Costs | W1: Case
S2: =P3*N5*L10*J15*H17*F25 -> 0 | W2: 1
S5: =P7*N5*L10*J15*H17*F25 -> 0 | W5: 0
S8: =P9*N12*L10*J15*H17*F25 -> 0 | W8: 1
S12: =P14*N12*L10*J15*H17*F25 -> 0 | W12: 0
S15: =P16*L17*J15*H17*F25 -> 0 | W15: 1
S18: =P19*L17*J15*H17*F25 -> 0 | W18: 0
S20: =P21*J23*H17*F25 -> 0 | W20: 1
F23: Syphilis +
S24: =P25*J23*H17*F25 -> 0 | W24: 0
F25: =p_prev -> 0.109
S27: =P28*H30*F25 -> 0 | W27: 1
D29: Test & Treat
S31: =P31*H30*F25 -> 0 | W31: 0
S33: =P34*L39*J44*H46*F54 -> 0 | W33: 1
S40: =P41*L39*J44*H46*F54 -> 0 | W40: 0
S44: =P45*L46*J44*H46*F54 -> 0 | W44: 1
S46: =P48*L46*J44*H46*F54 -> 0 | W46: 0
S49: =P50*J52*H46*F54 -> 0 | W49: 1
F52: Syphilis -
S53: =P54*J52*H46*F54 -> 0 | W53: 0
F54: =1-p_prev -> 0.891
S56: =P57*H59*F54 -> 0 | W56: 1
S59: =P60*H59*F54 -> 0 | W59: 0
J62: Expected values with test & treat | S62: =SUM(S2:S61) -> 0 | U62: =SUMPRODUCT(S15:S31,U15:U31) -> 0 | W62: =SUMPRODUCT(S2:S61,W2:W61) -> 0
S66: =P67*F69 -> 0 | W66: 1
D70: No Intervention | S70: =P71*F69 -> 0 | W70: 0
S73: =P74*F77 -> 0 | W73: 1
S79: =P80*F77 -> 0 | W79: 0
J82: Expected values with no intervention | S82: =SUM(S64:S81) -> 0 | U82: =SUMPRODUCT(S35:S51,U35:U51) -> 0 | W82: =SUMPRODUCT(S64:S81,W64:W81) -> 0
S86: =P87*J90*H95*F103 -> 0 | W86: 1
S90: =P91*J90*H95*F103 -> 0 | W90: 0
S93: =P95*J98*H95*F103 -> 0 | W93: 1
S98: =P99*J98*H95*F103 -> 0 | W98: 0
S105: =P106*H108*F103 -> 0 | W105: 1
D107: Treat All
S109: =P109*H108*F103 -> 0 | W109: 0
S111: =P112*H117*F122 -> 0 | W111: 1
S117: =P119*H117*F122 -> 0 | W117: 0
S125: =P126*H128*F122 -> 0 | W125: 1
...

Sheet Results_Ex2D
A1: RESULTS TABLE
A2: Strategy | B2: Total probability | C2: Expected deaths | D2: Expected YLLs | E2: Expected cost | F2: Check against Amua
A3: No Intervention | B3: =DT_template_Ex2B_C!S82 -> 0 | C3: =DT_template_Ex2B_C!W82 -> 0 | D3: =C3*Parameters_Ex2A!$E$16 -> 0 | E3: =DT_template_Ex2B_C!U82 -> 0 | F3: Target cost 0.00; target deaths 0.1090
A4: Test and Treat | B4: =DT_template_Ex2B_C!S62 -> 0 | C4: =DT_template_Ex2B_C!W62 -> 0 | D4: =C4*Parameters_Ex2A!$E$16 -> 0 | E4: =DT_template_Ex2B_C!U62 -> 0 | F4: Target cost 2.61; target deaths 0.0971
A5: Treat All | B5: =DT_template_Ex2B_C!S131 -> 0 | C5: =DT_template_Ex2B_C!W131 -> 0 | D5: =C5*Parameters_Ex2A!$E$16 -> 0 | E5: =DT_template_Ex2B_C!U131 -> 0 | F5: Target cost 3.58; target deaths 0.0934

Sheet CEA_Summary_Ex2D
A1: CEA SUMMARY
A2: Strategy | B2: Cost | C2: Count | D2: Incremental Cost | E2: Deaths Averted | F2: ICER | G2: Notes
A3: No Intervention | B3: =Results_Ex2D!E3 -> 0 | C3: =Results_Ex2D!C3 -> 0 | D3: - | E3: - | F3: - | G3: Baseline
A4: Test and Treat | B4: =Results_Ex2D!E4 -> 0 | C4: =Results_Ex2D!C4 -> 0 | D4: =B4-B3 -> 0 | E4: =C3-C4 -> 0 | F4: =D4/E4 -> #DIV/0! | G4: Compared with No Intervention
A5: Treat All | B5: =Results_Ex2D!E5 -> 0 | C5: =Results_Ex2D!C5 -> 0 | D5: =B5-B4 -> 0 | E5: =C4-C5 -> 0 | F5: =D5/E5 -> #DIV/0! | G5: Compared with Test and Treat
